Workbook

Sheet Cover
E3: THE NORWOOD FILES | H3: NF-CW1 · v1.0
B9: OFFICIAL COMPANION WORKBOOK
B11: The Row That Wasn’t There
B12: A Novel About Process Risk, Corrective Action and the Register That Missed the Factory
B15: Companion to Book One
B16: The forms from the book, with the rules already written into the formulas.
B21: REVISION | C21: v1.0 · NF-CW1
B22: EDITION | C22: Current to the 2026 edition of ISO 9001
B23: BASELINE | C23: Matches the first edition of the book (Editorial Baseline EBL-3.1)
B24: ISSUED | C24: 22 August 2026
B28: Dan Bleigh
B29: The Norwood Files

Sheet WELCOME
E2: THE NORWOOD FILES | H2: NF-CW1 · v1.0
B5: WELCOME
B7: WHAT THIS COMPANION IS FOR
B8: This workbook is the working half of Book One of The Norwood Files. It carries the forms from the book with the rules already written into the formulas, so that the method can be run on a real process instead of read about. Its subject is building and operating a process risk register: process flow, calibrated scales, the trigger rule, the action hierarchy, effectiveness verification and supplier risk.
B14: HOW TO USE IT
B15: Work top to bottom, in sheet order. Enter your own data; the calculated columns look after themselves. Nothing in the book depends on this file — every form is printed in full in the book and can be photocopied or rebuilt by hand. This file exists because typing formulas is not a good use of your afternoon.
B20: RELATIONSHIP WITH THE BOOK
B21: The numbered sheets carry the same Form numbers as the book. Form 3 in the book is Form 3 in this file. The sheets prefixed EXAMPLE are the worked cases from the book, complete and populated, so that you can see how a row behaves before you clear it and start on your own process.
B26: READING RECOMMENDATION
B27: Read the book’s narrative chapters first, then open this file with the book beside you. If you are working to a deadline, read the EXAMPLE sheet closest to your operation, then start on your own process — and read the chapters afterwards, because the reasoning is the transferable part.
B32: CONVENTIONS USED THROUGHOUT
B33: · | C33: Blue text on cream — you type here.
B34: · | C34: Black bold — calculated. Do not overwrite.
B35: · | C35: Yellow fill — attention: a value that needs a decision.
B36: · | C36: Red ■ — a fired trigger, or a finding. Red is never used for decoration.
B39: THE SHEETS IN THIS WORKBOOK
B40: SHEET | C40: PURPOSE
B41: START HERE | C41: Orientation, order of work, the trigger rule and the cell conventions.
B42: Form 1 Process Flow | C42: One row per place the product can be changed, damaged, measured wrongly or mixed up.
B43: Rating Scales | C43: Severity, occurrence and detection, calibrated to your own consequences and your own scrap data.
B44: Form 2 Risk Register | C44: The register itself. RPN, the trigger and the residual RPN calculate themselves. 200 rows.
B45: Form 3 Action Plan | C45: One line per triggered row, with an owner and a verification method defined before the action starts.
B46: Form 4 Review Log | C46: Evidence that the assessment is alive — one entry per review, scheduled or triggered.
B47: Form 5 Supplier Risk | C47: The five questions, for every supplier whose failure would reach your customer.
B48: Dashboard | C48: Triggered rows counted, initial against residual risk charted.
B49: Audit Evidence Map | C49: Which document answers which requirement — the sheet you hand to an auditor.
B50: EXAMPLE A Machining | C50: Worked register: CNC machining of a cast-iron housing. Complete, from the book.
B51: EXAMPLE B Coating | C51: Worked register: fusion-bonded epoxy pipe coating line. Complete, from the book.
... B53: About | C53: Instrument identity, document code and control status.
B56: OFFICIAL COMPANION RESOURCES
B57: The official repository holds this workbook, the other Companions in the series, and any corrected or updated revisions. There is nothing to sign up for and no address to leave.
B61: ‹ PH-01 · Companion download address — to be inserted before publication. NF-CIP §5. ›
B64: QR CODE RESERVED ‹ PH-02 › | E64: When the repository is published, the address and its QR code are placed here, and in Appendix B of the book. Until then this space is deliberately left blank rather than filled with an address that does not yet resolve. See the traceability table in NF-CIP §5.

Sheet LICENCE
E2: THE NORWOOD FILES | H2: NF-CW1 · v1.0
B5: LICENCE AND VERSION
B7: PUBLICATION INFORMATION
B8: PRODUCT | D8: Official Companion Workbook
B9: TITLE | D9: The Norwood Files — Companion to Book One
B10: COMPANION TO | D10: The Row That Wasn’t There
B11: DOCUMENT CODE | D11: NF-CW1
B12: REVISION | D12: v1.0
B13: PUBLICATION VERSION | D13: v1.0 · issued 22 August 2026
B14: EDITION | D14: Current to the 2026 edition of ISO 9001
B15: EDITORIAL BASELINE | D15: EBL-3.1
B16: IDENTITY | D16: Norwood Brand Standards Manual v1.0
B17: AUTHOR | D17: Dan Bleigh
B20: REPOSITORY
B21: ‹ PH-01 · Companion download address — to be inserted before publication. NF-CIP §5. ›
B23: TERMS OF USE
B24: Copyright © 2026 Dan Bleigh. All rights reserved.
B27: This workbook accompanies The Row That Wasn’t There and is supplied free of charge with the book. You may use it, adapt it and reproduce it inside your own organization for your own quality management system.
B31: You may not resell it, redistribute it as your own work, or present it as a certified or accredited document.
B34: The forms are offered as general professional guidance. They do not constitute legal, regulatory, safety or certification advice, and no warranty is given as to any particular audit outcome.
B38: ISO 9001 is an International Standard published by the International Organization for Standardization. This workbook is independent commentary and is not published, endorsed, sponsored or authorized by ISO, by any national standards body, or by any certification or accreditation body.
B46: Controlled document. Changes to this instrument follow the Norwood Brand Standards Manual Part XII and NF-ECP 4.6.

Sheet START HERE
A1: PROCESS RISK ANALYSIS AND CORRECTIVE ACTION
A2: Companion workbook. Free, no sign-up. Everything here is also printed in the book.
A4: WHAT THIS IS
B5: The forms from Part 3 of the book, with the trigger rule already written into the formulas, plus the three worked registers from Part 2 as completed examples.
B6: Nothing in the book depends on this file. Every form is printed in full and can be photocopied.
A7: ORDER OF WORK
B8: 1. Map your process on 'Form 1 Process Flow'. One row per place the product can be changed, damaged, measured wrongly or mixed up—not one row per machine.
B9: 2. Calibrate 'Rating Scales' to your own consequences and your own scrap data. Occurrence must come from your nonconformance log, not from memory.
B10: 3. Fill 'Form 2 Risk Register'. RPN, the trigger and the residual RPN calculate themselves.
B11: 4. Every triggered row gets a line on 'Form 3 Action Plan' with an owner and a verification method defined BEFORE the action, not after.
B12: 5. Record each review on 'Form 4 Review Log'. Assess suppliers on 'Form 5 Supplier Risk'.
A13: THE TRIGGER RULE
B14: Action is mandatory when severity reaches 9, when RPN reaches 100, or when severity is 7 or above AND detection is 7 or above. It is already in the formulas. Do not soften it after scoring.
A15: SEVERITY DOES NOT MOVE
B16: The 'Check' column turns red if a residual severity differs from the initial severity. Adding an inspection lowers detection. Adding a control lowers occurrence. Only a change to the product or the process lowers severity.
A17: CAPACITY
B18: The register holds 200 rows. Formulas are already in place on every one of them, so you can simply type into the next empty row and everything recalculates. Blank rows stay blank.
A19: SHEET NAMES
B20: The numbered sheets carry the same Form numbers as Part 3 of the book. Form 3 in the book is Form 3 in this file. The Rating Scales sheet is section 3.2 of the book and is deliberately unnumbered.
A21: THE EXAMPLES
B22: The three sheets prefixed EXAMPLE are complete registers from the book. Read the one closest to your operation, then work in 'Form 2 Risk Register'. Do not edit the examples—a register that still contains somebody else’s failure modes is found by an auditor with one question.
A23: CELL COLOURS
B24: Blue text on cream = you type here. Black bold = calculated, do not overwrite.
A26: The Norwood Files · Companion to Book One · v1.0 · issued 22 August 2026 · matches the first edition (Editorial Baseline EBL-3.1)

Sheet Form 1 Process Flow
A1: PROCESS FLOW
A2: Include storage, transport, setup, hand operations, inspection and the rework loop.
A4: Step | B4: Operation | C4: Purpose | D4: Key process parameters | E4: Control at this step

Sheet Rating Scales
A1: RATING SCALES
A2: Overwrite every line. A scale you have not edited is a scale from somebody else’s factory.
A4: SEVERITY (S) | D4: OCCURRENCE (O) | G4: DETECTION (D)
A5: Score | B5: In your plant this means | C5: The test that settles a dispute | D5: Score | E5: In your plant this means | F5: The test that settles a dispute | G5: Score | H5: In your plant this means | I5: The test that settles a dispute
A6: 10 | D6: 9–10 | G6: 10 | H6: No control. Found by the customer, or not at all.
A7: 9 | D7: 7–8 | G7: 8 | H7: Found downstream, or by the next process owner.
A8: 7–8 | D8: 5–6 | G8: 7 | H8: Operator visual or judgment. No record.
A9: 5–6 | D9: 3–4 | G9: 5 | H9: 100% final inspection, manual, recorded.
A10: 3–4 | D10: 1–2 | G10: 4 | H10: Sample-based automated test.
A11: 1–2 | G11: 3 | H11: 100% automated in process, recorded per part.
D12: Anchor on your own data. Scrap taken at the machine is usually not in the NCR log—tally it for four weeks first. | G12: 2 | H12: Automated with alarm or automatic hold.
A13: The most useful question is rarely 'how bad is the damage' but 'who finds it, and when'. | G13: 1 | H13: Error-proofed. Cannot occur, or cannot pass.
G15: Rate the control running today, on the cell where the part actually runs. Find the record before you write the number.
A18: TRIGGER RULE—write it down before the first line is scored
A19: Severity >= 9 | B19: Mandatory action regardless of RPN
A20: RPN >= 100 | B20: Mandatory action
A21: Severity >= 7 AND Detection >= 7 | B21: Mandatory action—serious failure, weak detection
A22: All other cases | B22: Monitor at a defined interval

Sheet Form 2 Risk Register
A1: FORM 2 RISK REGISTER
A2: 200 rows of capacity. Formulas are already in place—type into the next empty row.
A4: Risk ID | B4: Step | C4: Process step | D4: Failure mode | E4: Effect of failure | F4: S | G4: Cause | H4: O | I4: Current control | J4: D | K4: RPN | L4: Trigger | M4: Action ID | N4: Action level | O4: Res. S | P4: Res. O | Q4: Res. D | R4: Res. RPN | S4: Check
K5: =IF(COUNT(F5,H5,J5)=3,F5*H5*J5,"") | L5: =IF(K5="","",IF(OR(F5>=9,K5>=100,AND(F5>=7,J5>=7)),"ACTION REQUIRED","Monitor")) | R5: =IF(COUNT(O5,P5,Q5)=3,O5*P5*Q5,"") | S5: =IF(AND(O5<>"",F5<>"",O5<>F5),"SEVERITY CHANGED","")
K6: =IF(COUNT(F6,H6,J6)=3,F6*H6*J6,"") | L6: =IF(K6="","",IF(OR(F6>=9,K6>=100,AND(F6>=7,J6>=7)),"ACTION REQUIRED","Monitor")) | R6: =IF(COUNT(O6,P6,Q6)=3,O6*P6*Q6,"") | S6: =IF(AND(O6<>"",F6<>"",O6<>F6),"SEVERITY CHANGED","")
K7: =IF(COUNT(F7,H7,J7)=3,F7*H7*J7,"") | L7: =IF(K7="","",IF(OR(F7>=9,K7>=100,AND(F7>=7,J7>=7)),"ACTION REQUIRED","Monitor")) | R7: =IF(COUNT(O7,P7,Q7)=3,O7*P7*Q7,"") | S7: =IF(AND(O7<>"",F7<>"",O7<>F7),"SEVERITY CHANGED","")
K8: =IF(COUNT(F8,H8,J8)=3,F8*H8*J8,"") | L8: =IF(K8="","",IF(OR(F8>=9,K8>=100,AND(F8>=7,J8>=7)),"ACTION REQUIRED","Monitor")) | R8: =IF(COUNT(O8,P8,Q8)=3,O8*P8*Q8,"") | S8: =IF(AND(O8<>"",F8<>"",O8<>F8),"SEVERITY CHANGED","")
K9: =IF(COUNT(F9,H9,J9)=3,F9*H9*J9,"") | L9: =IF(K9="","",IF(OR(F9>=9,K9>=100,AND(F9>=7,J9>=7)),"ACTION REQUIRED","Monitor")) | R9: =IF(COUNT(O9,P9,Q9)=3,O9*P9*Q9,"") | S9: =IF(AND(O9<>"",F9<>"",O9<>F9),"SEVERITY CHANGED","")
K10: =IF(COUNT(F10,H10,J10)=3,F10*H10*J10,"") | L10: =IF(K10="","",IF(OR(F10>=9,K10>=100,AND(F10>=7,J10>=7)),"ACTION REQUIRED","Monitor")) | R10: =IF(COUNT(O10,P10,Q10)=3,O10*P10*Q10,"") | S10: =IF(AND(O10<>"",F10<>"",O10<>F10),"SEVERITY CHANGED","")
K11: =IF(COUNT(F11,H11,J11)=3,F11*H11*J11,"") | L11: =IF(K11="","",IF(OR(F11>=9,K11>=100,AND(F11>=7,J11>=7)),"ACTION REQUIRED","Monitor")) | R11: =IF(COUNT(O11,P11,Q11)=3,O11*P11*Q11,"") | S11: =IF(AND(O11<>"",F11<>"",O11<>F11),"SEVERITY CHANGED","")
K12: =IF(COUNT(F12,H12,J12)=3,F12*H12*J12,"") | L12: =IF(K12="","",IF(OR(F12>=9,K12>=100,AND(F12>=7,J12>=7)),"ACTION REQUIRED","Monitor")) | R12: =IF(COUNT(O12,P12,Q12)=3,O12*P12*Q12,"") | S12: =IF(AND(O12<>"",F12<>"",O12<>F12),"SEVERITY CHANGED","")
K13: =IF(COUNT(F13,H13,J13)=3,F13*H13*J13,"") | L13: =IF(K13="","",IF(OR(F13>=9,K13>=100,AND(F13>=7,J13>=7)),"ACTION REQUIRED","Monitor")) | R13: =IF(COUNT(O13,P13,Q13)=3,O13*P13*Q13,"") | S13: =IF(AND(O13<>"",F13<>"",O13<>F13),"SEVERITY CHANGED","")
K14: =IF(COUNT(F14,H14,J14)=3,F14*H14*J14,"") | L14: =IF(K14="","",IF(OR(F14>=9,K14>=100,AND(F14>=7,J14>=7)),"ACTION REQUIRED","Monitor")) | R14: =IF(COUNT(O14,P14,Q14)=3,O14*P14*Q14,"") | S14: =IF(AND(O14<>"",F14<>"",O14<>F14),"SEVERITY CHANGED","")
K15: =IF(COUNT(F15,H15,J15)=3,F15*H15*J15,"") | L15: =IF(K15="","",IF(OR(F15>=9,K15>=100,AND(F15>=7,J15>=7)),"ACTION REQUIRED","Monitor")) | R15: =IF(COUNT(O15,P15,Q15)=3,O15*P15*Q15,"") | S15: =IF(AND(O15<>"",F15<>"",O15<>F15),"SEVERITY CHANGED","")
K16: =IF(COUNT(F16,H16,J16)=3,F16*H16*J16,"") | L16: =IF(K16="","",IF(OR(F16>=9,K16>=100,AND(F16>=7,J16>=7)),"ACTION REQUIRED","Monitor")) | R16: =IF(COUNT(O16,P16,Q16)=3,O16*P16*Q16,"") | S16: =IF(AND(O16<>"",F16<>"",O16<>F16),"SEVERITY CHANGED","")
... K204: =IF(COUNT(F204,H204,J204)=3,F204*H204*J204,"") | L204: =IF(K204="","",IF(OR(F204>=9,K204>=100,AND(F204>=7,J204>=7)),"ACTION REQUIRED","Monitor")) | R204: =IF(COUNT(O204,P204,Q204)=3,O204*P204*Q204,"") | S204: =IF(AND(O204<>"",F204<>"",O204<>F204),"SEVERITY CHANGED","")

Sheet Form 3 Action Plan
A1: ACTION PLAN AND EFFECTIVENESS VERIFICATION
A2: The four verification fields are completed when the action is RAISED, not when it closes.
A4: Action ID | B4: Risk ID | C4: Action taken | D4: Hierarchy level | E4: Owner (name) | F4: Raised | G4: Due | H4: NCR / CAPA link | I4: Verification method | J4: Baseline (rate and quantity) | K4: Success criterion | L4: Result and date
A126: An action at level 5 is highlighted. Procedure and training reduce escape, not risk, and are never sufficient on their own for a high-severity failure. Wait until the pre-action failure rate would have produced three to five occurrences before you record a result—measure exposure, not calendar time.

Sheet Form 4 Review Log
A1: REVIEW LOG
A2: Evidence that the assessment is alive. Triggered by events, not by the calendar.
A4: Date | B4: What triggered it | C4: Present | D4: Changes made | E4: Next review due | F4: Approved by

Sheet Form 5 Supplier Risk
A1: SUPPLIER RISK ASSESSMENT
A2: For every supplier whose failure would reach your customer. The questions cannot be answered with a tick.
A4: Supplier | B4: Question | C4: Answer and evidence | D4: Register rows raised
B5: 1. What do they supply, and what fails if it is wrong?
B6: 2. Can we detect their failure before it reaches our customer?
B7: 3. Is there a qualified alternative, and how long to switch?
B8: 4. What do we know about their process control, and how do we know it?
B9: 5. What changes at their end would we not be told about?
B10: 1. What do they supply, and what fails if it is wrong?
B11: 2. Can we detect their failure before it reaches our customer?
B12: 3. Is there a qualified alternative, and how long to switch?
B13: 4. What do we know about their process control, and how do we know it?
B14: 5. What changes at their end would we not be told about?
B15: 1. What do they supply, and what fails if it is wrong?
B16: 2. Can we detect their failure before it reaches our customer?
... B44: 5. What changes at their end would we not be told about?

Sheet Dashboard
A1: RISK PROFILE DASHBOARD
A2: Calculated live from 'Form 2 Risk Register'. Nothing on this sheet is typed.
A4: FAILURE MODES | C4: ACTION REQUIRED | E4: SEVERITY 9 OR 10 | G4: HIGHEST RPN | I4: RISK REDUCTION
A5: =COUNTA('Form 2 Risk Register'!A5:A204) | C5: =COUNTIF('Form 2 Risk Register'!L5:L204,"ACTION REQUIRED") | E5: =COUNTIF('Form 2 Risk Register'!F5:F204,">=9") | G5: =IFERROR(MAX('Form 2 Risk Register'!K5:K204),0) | I5: =IFERROR(1-SUM('Form 2 Risk Register'!R5:R204)/SUM('Form 2 Risk Register'!K5:K204),"")
A7: assessed | C7: trigger rule fired | E7: mandatory regardless of RPN | G7: initial assessment | I7: after verified actions
A43: The step carrying the highest initial bar is where the process is least in control—normally the right place to start, not the step where defects are most visible. A hierarchy chart weighted toward levels 4 and 5 means you are reducing escape rather than risk.
A46: CHART SOURCE DATA—calculated, do not overwrite
A47: Process step | B47: Initial RPN | C47: Residual RPN
A48: Step 1 | B48: =SUMIF('Form 2 Risk Register'!$B$5:$B$204,1,'Form 2 Risk Register'!$K$5:$K$204) | C48: =SUMIF('Form 2 Risk Register'!$B$5:$B$204,1,'Form 2 Risk Register'!$R$5:$R$204)
A49: Step 2 | B49: =SUMIF('Form 2 Risk Register'!$B$5:$B$204,2,'Form 2 Risk Register'!$K$5:$K$204) | C49: =SUMIF('Form 2 Risk Register'!$B$5:$B$204,2,'Form 2 Risk Register'!$R$5:$R$204)
A50: Step 3 | B50: =SUMIF('Form 2 Risk Register'!$B$5:$B$204,3,'Form 2 Risk Register'!$K$5:$K$204) | C50: =SUMIF('Form 2 Risk Register'!$B$5:$B$204,3,'Form 2 Risk Register'!$R$5:$R$204)
A51: Step 4 | B51: =SUMIF('Form 2 Risk Register'!$B$5:$B$204,4,'Form 2 Risk Register'!$K$5:$K$204) | C51: =SUMIF('Form 2 Risk Register'!$B$5:$B$204,4,'Form 2 Risk Register'!$R$5:$R$204)
A52: Step 5 | B52: =SUMIF('Form 2 Risk Register'!$B$5:$B$204,5,'Form 2 Risk Register'!$K$5:$K$204) | C52: =SUMIF('Form 2 Risk Register'!$B$5:$B$204,5,'Form 2 Risk Register'!$R$5:$R$204)
A53: Step 6 | B53: =SUMIF('Form 2 Risk Register'!$B$5:$B$204,6,'Form 2 Risk Register'!$K$5:$K$204) | C53: =SUMIF('Form 2 Risk Register'!$B$5:$B$204,6,'Form 2 Risk Register'!$R$5:$R$204)
A54: Step 7 | B54: =SUMIF('Form 2 Risk Register'!$B$5:$B$204,7,'Form 2 Risk Register'!$K$5:$K$204) | C54: =SUMIF('Form 2 Risk Register'!$B$5:$B$204,7,'Form 2 Risk Register'!$R$5:$R$204)
A55: Step 8 | B55: =SUMIF('Form 2 Risk Register'!$B$5:$B$204,8,'Form 2 Risk Register'!$K$5:$K$204) | C55: =SUMIF('Form 2 Risk Register'!$B$5:$B$204,8,'Form 2 Risk Register'!$R$5:$R$204)
A56: Step 9 | B56: =SUMIF('Form 2 Risk Register'!$B$5:$B$204,9,'Form 2 Risk Register'!$K$5:$K$204) | C56: =SUMIF('Form 2 Risk Register'!$B$5:$B$204,9,'Form 2 Risk Register'!$R$5:$R$204)
A57: Step 10 | B57: =SUMIF('Form 2 Risk Register'!$B$5:$B$204,10,'Form 2 Risk Register'!$K$5:$K$204) | C57: =SUMIF('Form 2 Risk Register'!$B$5:$B$204,10,'Form 2 Risk Register'!$R$5:$R$204)
A58: Step 11 | B58: =SUMIF('Form 2 Risk Register'!$B$5:$B$204,11,'Form 2 Risk Register'!$K$5:$K$204) | C58: =SUMIF('Form 2 Risk Register'!$B$5:$B$204,11,'Form 2 Risk Register'!$R$5:$R$204)
A59: Step 12 | B59: =SUMIF('Form 2 Risk Register'!$B$5:$B$204,12,'Form 2 Risk Register'!$K$5:$K$204) | C59: =SUMIF('Form 2 Risk Register'!$B$5:$B$204,12,'Form 2 Risk Register'!$R$5:$R$204)
A60: Step 13 | B60: =SUMIF('Form 2 Risk Register'!$B$5:$B$204,13,'Form 2 Risk Register'!$K$5:$K$204) | C60: =SUMIF('Form 2 Risk Register'!$B$5:$B$204,13,'Form 2 Risk Register'!$R$5:$R$204)
A61: Step 14 | B61: =SUMIF('Form 2 Risk Register'!$B$5:$B$204,14,'Form 2 Risk Register'!$K$5:$K$204) | C61: =SUMIF('Form 2 Risk Register'!$B$5:$B$204,14,'Form 2 Risk Register'!$R$5:$R$204)
A64: Trigger status | B64: Count
A65: Action required | B65: =COUNTIF('Form 2 Risk Register'!L5:L204,"ACTION REQUIRED")
A66: Monitor | B66: =COUNTIF('Form 2 Risk Register'!L5:L204,"Monitor")
A69: Severity band | B69: Failure modes
A70: S 1–4 minor | B70: =COUNTIF('Form 2 Risk Register'!$F$5:$F$204,">=1")-COUNTIF('Form 2 Risk Register'!$F$5:$F$204,">=5")
A71: S 5–6 rework | B71: =COUNTIF('Form 2 Risk Register'!$F$5:$F$204,">=5")-COUNTIF('Form 2 Risk Register'!$F$5:$F$204,">=7")
A72: S 7–8 loss of function | B72: =COUNTIF('Form 2 Risk Register'!$F$5:$F$204,">=7")-COUNTIF('Form 2 Risk Register'!$F$5:$F$204,">=9")
A73: S 9–10 escape / safety | B73: =COUNTIF('Form 2 Risk Register'!$F$5:$F$204,">=9")
A76: Action level | B76: Actions
A77: 5 Procedure | B77: =COUNTIF('Form 3 Action Plan'!$D$5:$D$124,"5*")
A78: 4 Detection | B78: =COUNTIF('Form 3 Action Plan'!$D$5:$D$124,"4*")
A79: 3 Automated control | B79: =COUNTIF('Form 3 Action Plan'!$D$5:$D$124,"3*")
A80: 2 Error-proof | B80: =COUNTIF('Form 3 Action Plan'!$D$5:$D$124,"2*")
A81: 1 Eliminate cause | B81: =COUNTIF('Form 3 Action Plan'!$D$5:$D$124,"1*")

Sheet Audit Evidence Map
A1: AUDIT EVIDENCE MAP
A2: Which sheet answers which requirement. Clause numbers follow ISO 9001:2015.
A4: Clause | B4: What is required | C4: What you show them | D4: Sheet
A5: 4.4.1 | B5: The processes needed and their interaction | C5: The flow, including transport, setup and rework | D5: Form 1 Process Flow
A6: 6.1.1 | B6: Risks and opportunities determined | C6: A row against process steps, not against departments | D6: Form 2 Risk Register
A7: 6.1.2 a | B7: Actions planned to address them | C7: The trigger rule, dated before scoring, plus the action lines | D7: Rating Scales / Form 3 Action Plan
A8: 6.1.2 b | B8: Actions integrated and effectiveness evaluated | C8: Verification fields completed at raising, with the result | D8: Form 3 Action Plan
A9: 7.1.5 | B9: Monitoring and measuring resources fit for purpose | C9: Rows treating the inspection equipment itself as a failure mode | D9: Form 2 Risk Register
A10: 8.4 | B10: Control of externally provided processes and products | C10: A completed assessment for every critical supplier | D10: Form 5 Supplier Risk
A11: 8.5.1 | B11: Production under controlled conditions | C11: Current controls per row; actions that raise the control level | D11: Form 2 Risk Register
A12: 8.7 | B12: Control of nonconforming outputs | C12: The rework loop assessed as a process, with repair limits | D12: Form 2 Risk Register
A13: 9.3 | B13: Management review of the effectiveness of actions | C13: Dated entries with trigger, participants, changes, approval | D13: Form 4 Review Log
A14: 10.2 | B14: Corrective action—cause, action, effectiveness | C14: The NCR/CAPA link and the re-score on closure | D14: Form 3 Action Plan

Sheet EXAMPLE A Machining
A1: EXAMPLE A MACHINING
A2: CNC machining of a cast-iron housing—complete worked register from Part 2. Read, do not edit.
A4: Risk ID | B4: Step | C4: Process step | D4: Failure mode | E4: Effect of failure | F4: S | G4: Cause | H4: O | I4: Current control | J4: D | K4: RPN | L4: Trigger | M4: Action ID | N4: Action level | O4: Res. S | P4: Res. O | Q4: Res. D | R4: Res. RPN | S4: Check | T4: Action taken
A5: Step 1—Casting receipt and outside storage
A6: M-1.1 | B6: 1 | C6: Casting receipt | D6: Casting supplied with the bore boss offset from the outer form | E6: datum error carried into every subsequent dimension; interference fit lost at the customer | F6: 9 | G6: Foundry pattern defect, undetected at source | H6: 8 | I6: None at receipt | J6: 9 | K6: =IF(COUNT(F6,H6,J6)=3,F6*H6*J6,"") | L6: =IF(K6="","",IF(OR(F6>=9,K6>=100,AND(F6>=7,J6>=7)),"ACTION REQUIRED","Monitor")) | M6: A-01 | N6: 1 Eliminate cause | O6: 9 | P6: 2 | Q6: 4 | R6: =IF(COUNT(O6,P6,Q6)=3,O6*P6*Q6,"") | S6: =IF(AND(O6<>"",F6<>"",O6<>F6),"SEVERITY CHANGED","") | T6: Supplier pattern replaced and verified by first article (level 1). Incoming boss-to-form check, five castings per pallet, added as a standing control.
A7: M-1.2 | B7: 1 | C7: Casting receipt | D7: Casting corroded or damaged in outside storage | E7: surface defect, rework or scrap | F7: 5 | G7: Uncovered storage; handling on pallets | H7: 4 | I7: Visual at issue | J7: 6 | K7: =IF(COUNT(F7,H7,J7)=3,F7*H7*J7,"") | L7: =IF(K7="","",IF(OR(F7>=9,K7>=100,AND(F7>=7,J7>=7)),"ACTION REQUIRED","Monitor")) | M7: A-02 | N7: 3 Automated control | O7: 5 | P7: 2 | Q7: 4 | R7: =IF(COUNT(O7,P7,Q7)=3,O7*P7*Q7,"") | S7: =IF(AND(O7<>"",F7<>"",O7<>F7),"SEVERITY CHANGED","") | T7: Castings moved under cover on receipt; pallets rotated by FIFO; condition recorded at issue.
A8: M-1.3 | B8: 1 | C8: Casting receipt | D8: Casting machined below stabilization temperature | E8: dimensions drift after inspection | F8: 6 | G8: No hold time defined; winter delivery straight to first operation | H8: 6 | I8: None | J8: 8 | K8: =IF(COUNT(F8,H8,J8)=3,F8*H8*J8,"") | L8: =IF(K8="","",IF(OR(F8>=9,K8>=100,AND(F8>=7,J8>=7)),"ACTION REQUIRED","Monitor")) | M8: A-03 | N8: 3 Automated control | O8: 6 | P8: 2 | Q8: 4 | R8: =IF(COUNT(O8,P8,Q8)=3,O8*P8*Q8,"") | S8: =IF(AND(O8<>"",F8<>"",O8<>F8),"SEVERITY CHANGED","") | T8: Minimum stabilization hold defined before the first operation; recorded on the route card.
A9: Step 3—Face and locate
A10: M-3.1 | B10: 3 | C10: Face and locate | D10: Datum taken from a cast surface that is itself out of position | E10: all subsequent dimensions displaced | F10: 9 | G10: Core shift (see M-1.1); locating surface never verified | H10: 6 | I10: First-off only | J10: 7 | K10: =IF(COUNT(F10,H10,J10)=3,F10*H10*J10,"") | L10: =IF(K10="","",IF(OR(F10>=9,K10>=100,AND(F10>=7,J10>=7)),"ACTION REQUIRED","Monitor")) | M10: A-04 | N10: 4 Detection | O10: 9 | P10: 2 | Q10: 4 | R10: =IF(COUNT(O10,P10,Q10)=3,O10*P10*Q10,"") | S10: =IF(AND(O10<>"",F10<>"",O10<>F10),"SEVERITY CHANGED","") | T10: Locating surface verified on the first casting of each pallet against the incoming check result.
A11: Steps 5–6—Lathe setup and turning
A12: M-5.1 | B12: 5 | C12: Lathe setup | D12: First-off accepted at the tolerance limit rather than mid-band | E12: drift exits tolerance during the run | F12: 7 | G12: No rule on where in the band a first-off must sit | H12: 6 | I12: Operator judgment | J12: 7 | K12: =IF(COUNT(F12,H12,J12)=3,F12*H12*J12,"") | L12: =IF(K12="","",IF(OR(F12>=9,K12>=100,AND(F12>=7,J12>=7)),"ACTION REQUIRED","Monitor")) | M12: A-05 | N12: 2 Error-proof | O12: 7 | P12: 3 | Q12: 5 | R12: =IF(COUNT(O12,P12,Q12)=3,O12*P12*Q12,"") | S12: =IF(AND(O12<>"",F12<>"",O12<>F12),"SEVERITY CHANGED","") | T12: Setup instruction now specifies that a first-off must fall within the middle half of the band; a first-off at the limit is a reject.
A13: M-6.1 | B13: 6 | C13: Turning | D13: Outside diameter out of tolerance | E13: assembly interference at the customer | F13: 8 | G13: Insert wear; offset error at setup | H13: 4 | I13: First and last piece | J13: 6 | K13: =IF(COUNT(F13,H13,J13)=3,F13*H13*J13,"") | L13: =IF(K13="","",IF(OR(F13>=9,K13>=100,AND(F13>=7,J13>=7)),"ACTION REQUIRED","Monitor")) | M13: A-06 | N13: 3 Automated control | O13: 8 | P13: 2 | Q13: 4 | R13: =IF(COUNT(O13,P13,Q13)=3,O13*P13*Q13,"") | S13: =IF(AND(O13<>"",F13<>"",O13<>F13),"SEVERITY CHANGED","") | T13: Insert replacement moved to a run-hours schedule; offset verified by a second person at setup.
A14: Step 7—Move to cell two (shared trolley)
A15: M-7.1 | B15: 7 | C15: Move to cell two | D15: Impact damage to machined surfaces in transit | E15: rework or scrap | F15: 5 | G15: Unpadded shared trolley | H15: 5 | I15: Visual at next operation | J15: 6 | K15: =IF(COUNT(F15,H15,J15)=3,F15*H15*J15,"") | L15: =IF(K15="","",IF(OR(F15>=9,K15>=100,AND(F15>=7,J15>=7)),"ACTION REQUIRED","Monitor")) | M15: A-07 | N15: 2 Error-proof | O15: 5 | P15: 2 | Q15: 5 | R15: =IF(COUNT(O15,P15,Q15)=3,O15*P15*Q15,"") | S15: =IF(AND(O15<>"",F15<>"",O15<>F15),"SEVERITY CHANGED","") | T15: Dedicated part trolley with fitted dunnage; machined faces no longer contact steel or each other in transit.
A16: M-7.2 | B16: 7 | C16: Move to cell two | D16: Conforming and scrap parts carried together | E16: nonconforming part re-enters the flow | F16: 9 | G16: Same trolley carries the red bin; no physical segregation | H16: 3 | I16: Red bin convention only | J16: 8 | K16: =IF(COUNT(F16,H16,J16)=3,F16*H16*J16,"") | L16: =IF(K16="","",IF(OR(F16>=9,K16>=100,AND(F16>=7,J16>=7)),"ACTION REQUIRED","Monitor")) | M16: A-08 | N16: 2 Error-proof | O16: 9 | P16: 1 | Q16: 5 | R16: =IF(COUNT(O16,P16,Q16)=3,O16*P16*Q16,"") | S16: =IF(AND(O16<>"",F16<>"",O16<>F16),"SEVERITY CHANGED","") | T16: Red bin removed from the transport trolley and fixed at the machine. Physical segregation, not convention.
A17: Steps 8–9—Boring setup and bore
A18: M-8.1 | B18: 8 | C18: Boring setup | D18: Insert changed at an interval that does not reflect actual tool life | E18: progressive bore drift above the upper limit | F18: 9 | G18: Setup card interval taken from a catalog and never validated; casting variation accelerates wear | H18: 8 | I18: First and last piece only; mid-run unmeasured | J18: 7 | K18: =IF(COUNT(F18,H18,J18)=3,F18*H18*J18,"") | L18: =IF(K18="","",IF(OR(F18>=9,K18>=100,AND(F18>=7,J18>=7)),"ACTION REQUIRED","Monitor")) | M18: A-09 | N18: 1 Eliminate cause | O18: 9 | P18: 2 | Q18: 5 | R18: =IF(COUNT(O18,P18,Q18)=3,O18*P18*Q18,"") | S18: =IF(AND(O18<>"",F18<>"",O18<>F18),"SEVERITY CHANGED","") | T18: Root cause reassigned after three-year history review: casting variation, not tool life. Pattern replaced (see M-1.1). Interval corrected to 300 on the setup card.
A19: M-8.2 | B19: 8 | C19: Boring setup | D19: Boring offset entered incorrectly at setup | E19: bore oversize or undersize from the first part | F19: 8 | G19: Manual entry; no verification beyond the first-off | H19: 3 | I19: First-off | J19: 5 | K19: =IF(COUNT(F19,H19,J19)=3,F19*H19*J19,"") | L19: =IF(K19="","",IF(OR(F19>=9,K19>=100,AND(F19>=7,J19>=7)),"ACTION REQUIRED","Monitor")) | M19: A-10 | N19: 5 Procedure | O19: 8 | P19: 2 | Q19: 5 | R19: =IF(COUNT(O19,P19,Q19)=3,O19*P19*Q19,"") | S19: =IF(AND(O19<>"",F19<>"",O19<>F19),"SEVERITY CHANGED","") | T19: Offset confirmed against a written value at setup and countersigned.
A20: Step 10—Deburr bench (no owner)
A21: M-10.1 | B21: 10 | C21: Deburr bench | D21: Burr left in the bore | E21: seal damage at customer assembly | F21: 7 | G21: Bench has no instruction and no acceptance criterion | H21: 5 | I21: Visual | J21: 7 | K21: =IF(COUNT(F21,H21,J21)=3,F21*H21*J21,"") | L21: =IF(K21="","",IF(OR(F21>=9,K21>=100,AND(F21>=7,J21>=7)),"ACTION REQUIRED","Monitor")) | M21: A-11 | N21: 3 Automated control | O21: 7 | P21: 3 | Q21: 5 | R21: =IF(COUNT(O21,P21,Q21)=3,O21*P21*Q21,"") | S21: =IF(AND(O21<>"",F21<>"",O21<>F21),"SEVERITY CHANGED","") | T21: Deburr bench given an operation number, an owner and a written acceptance criterion. Bore check added at the bench.
A22: M-10.2 | B22: 10 | C22: Deburr bench | D22: Handling damage to the bore at the bench | E22: surface defect | F22: 6 | G22: Parts handled by hand without a fixture | H22: 4 | I22: Visual | J22: 7 | K22: =IF(COUNT(F22,H22,J22)=3,F22*H22*J22,"") | L22: =IF(K22="","",IF(OR(F22>=9,K22>=100,AND(F22>=7,J22>=7)),"ACTION REQUIRED","Monitor")) | M22: A-12 | N22: 2 Error-proof | O22: 6 | P22: 2 | Q22: 5 | R22: =IF(COUNT(O22,P22,Q22)=3,O22*P22*Q22,"") | S22: =IF(AND(O22<>"",F22<>"",O22<>F22),"SEVERITY CHANGED","") | T22: Simple location fixture at the deburr bench; the bore is no longer handled to position the part.
A23: Step 11—Wash
A24: M-11.1 | B24: 11 | C24: Wash | D24: Residual swarf or coolant left in the bore | E24: contamination at customer assembly | F24: 7 | G24: Wash cycle never validated for blind features | H24: 4 | I24: Visual | J24: 7 | K24: =IF(COUNT(F24,H24,J24)=3,F24*H24*J24,"") | L24: =IF(K24="","",IF(OR(F24>=9,K24>=100,AND(F24>=7,J24>=7)),"ACTION REQUIRED","Monitor")) | M24: A-13 | N24: 3 Automated control | O24: 7 | P24: 2 | Q24: 5 | R24: =IF(COUNT(O24,P24,Q24)=3,O24*P24*Q24,"") | S24: =IF(AND(O24<>"",F24<>"",O24<>F24),"SEVERITY CHANGED","") | T24: Wash cycle validated for the blind bore; cleanliness criterion defined and sampled.
A25: Step 12—Final inspection
A26: M-12.1 | B26: 12 | C26: Final inspection | D26: Bore gauge out of calibration | E26: out-of-tolerance parts accepted | F26: 8 | G26: Annual calibration only; no verification at shift start | H26: 3 | I26: Calibration label | J26: 7 | K26: =IF(COUNT(F26,H26,J26)=3,F26*H26*J26,"") | L26: =IF(K26="","",IF(OR(F26>=9,K26>=100,AND(F26>=7,J26>=7)),"ACTION REQUIRED","Monitor")) | M26: A-14 | N26: 4 Detection | O26: 8 | P26: 2 | Q26: 3 | R26: =IF(COUNT(O26,P26,Q26)=3,O26*P26*Q26,"") | S26: =IF(AND(O26<>"",F26<>"",O26<>F26),"SEVERITY CHANGED","") | T26: Zero and reference verification of the bore gauge at each shift start, recorded on the inspection sheet.
A27: M-12.2 | B27: 12 | C27: Final inspection | D27: Parts measured before reaching ambient | E27: dimensions recorded at the wrong temperature | F27: 7 | G27: No hold time before measurement | H27: 5 | I27: None | J27: 8 | K27: =IF(COUNT(F27,H27,J27)=3,F27*H27*J27,"") | L27: =IF(K27="","",IF(OR(F27>=9,K27>=100,AND(F27>=7,J27>=7)),"ACTION REQUIRED","Monitor")) | M27: A-15 | N27: 3 Automated control | O27: 7 | P27: 2 | Q27: 4 | R27: =IF(COUNT(O27,P27,Q27)=3,O27*P27*Q27,"") | S27: =IF(AND(O27<>"",F27<>"",O27<>F27),"SEVERITY CHANGED","") | T27: Hold time before measurement defined and enforced by the inspection queue.
A28: Step 13—Rework loop
A29: M-13.1 | B29: 13 | C29: Rework loop | D29: Repeated rework on the same part | E29: wall thickness below drawing minimum | F29: 9 | G29: No cumulative rework limit or record per part | H29: 4 | I29: Operator judgment | J29: 8 | K29: =IF(COUNT(F29,H29,J29)=3,F29*H29*J29,"") | L29: =IF(K29="","",IF(OR(F29>=9,K29>=100,AND(F29>=7,J29>=7)),"ACTION REQUIRED","Monitor")) | M29: A-16 | N29: 3 Automated control | O29: 9 | P29: 2 | Q29: 4 | R29: =IF(COUNT(O29,P29,Q29)=3,O29*P29*Q29,"") | S29: =IF(AND(O29<>"",F29<>"",O29<>F29),"SEVERITY CHANGED","") | T29: Rework log per part identifier with a cumulative limit; QA disposition required above it.
A30: M-13.2 | B30: 13 | C30: Rework loop | D30: Reworked part released without re-inspection | E30: nonconforming part shipped | F30: 10 | G30: Step skipped under schedule pressure; procedural control only | H30: 3 | I30: QA signature | J30: 6 | K30: =IF(COUNT(F30,H30,J30)=3,F30*H30*J30,"") | L30: =IF(K30="","",IF(OR(F30>=9,K30>=100,AND(F30>=7,J30>=7)),"ACTION REQUIRED","Monitor")) | M30: A-17 | N30: 2 Error-proof | O30: 10 | P30: 1 | Q30: 2 | R30: =IF(COUNT(O30,P30,Q30)=3,O30*P30*Q30,"") | S30: =IF(AND(O30<>"",F30<>"",O30<>F30),"SEVERITY CHANGED","") | T30: Release blocked in the system until a re-inspection result is recorded against the part.
A31: Step 14—Pack and dispatch
A32: M-14.1 | B32: 14 | C32: Pack and dispatch | D32: Identification lost between inspection and pack | E32: wrong parts shipped; traceability broken | F32: 9 | G32: Marking removed by wash; manual transcription | H32: 4 | I32: Manual record | J32: 6 | K32: =IF(COUNT(F32,H32,J32)=3,F32*H32*J32,"") | L32: =IF(K32="","",IF(OR(F32>=9,K32>=100,AND(F32>=7,J32>=7)),"ACTION REQUIRED","Monitor")) | M32: A-18 | N32: 2 Error-proof | O32: 9 | P32: 2 | Q32: 3 | R32: =IF(COUNT(O32,P32,Q32)=3,O32*P32*Q32,"") | S32: =IF(AND(O32<>"",F32<>"",O32<>F32),"SEVERITY CHANGED","") | T32: Durable re-marking after wash; identifier scanned at pack against the inspection record.
A33: Supplier—added after the second surveillance audit
A34: M-S.1 | B34: S | C34: Supplier | D34: Foundry ceases supply or loses capability | E34: no source for the casting; production stops | F34: 9 | G34: Single source since 2015; no qualified alternative; 7–11 months to qualify one | H34: 2 | I34: None | J34: 10 | K34: =IF(COUNT(F34,H34,J34)=3,F34*H34*J34,"") | L34: =IF(K34="","",IF(OR(F34>=9,K34>=100,AND(F34>=7,J34>=7)),"ACTION REQUIRED","Monitor")) | M34: A-19 | N34: — none affordable | O34: 9 | P34: 2 | Q34: 10 | R34: =IF(COUNT(O34,P34,Q34)=3,O34*P34*Q34,"") | S34: =IF(AND(O34<>"",F34<>"",O34<>F34),"SEVERITY CHANGED","") | T34: Accepted with rationale by the operations manager; second-source qualification costed and deferred to the April budget; reviewed at each management review.
K35: =IF(COUNT(F35,H35,J35)=3,F35*H35*J35,"") | L35: =IF(K35="","",IF(OR(F35>=9,K35>=100,AND(F35>=7,J35>=7)),"ACTION REQUIRED","Monitor")) | R35: =IF(COUNT(O35,P35,Q35)=3,O35*P35*Q35,"") | S35: =IF(AND(O35<>"",F35<>"",O35<>F35),"SEVERITY CHANGED","")
K36: =IF(COUNT(F36,H36,J36)=3,F36*H36*J36,"") | L36: =IF(K36="","",IF(OR(F36>=9,K36>=100,AND(F36>=7,J36>=7)),"ACTION REQUIRED","Monitor")) | R36: =IF(COUNT(O36,P36,Q36)=3,O36*P36*Q36,"") | S36: =IF(AND(O36<>"",F36<>"",O36<>F36),"SEVERITY CHANGED","")

Sheet EXAMPLE B Coating
A1: EXAMPLE B COATING
A2: Fusion-bonded epoxy pipe coating line—complete worked register from Part 2. Read, do not edit.
A4: Risk ID | B4: Step | C4: Process step | D4: Failure mode | E4: Effect of failure | F4: S | G4: Cause | H4: O | I4: Current control | J4: D | K4: RPN | L4: Trigger | M4: Action ID | N4: Action level | O4: Res. S | P4: Res. O | Q4: Res. D | R4: Res. RPN | S4: Check | T4: Action taken
A5: Stage 1—Surface preparation
A6: C-1.1 | B6: 1 | C6: Surface preparation | D6: Anchor profile below specification | E6: insufficient adhesion; disbondment in service; pipeline corrosion | F6: 9 | G6: Degraded or undersized abrasive; low blast pressure | H6: 5 | I6: Replica tape, sampled each shift | J6: 6 | K6: =IF(COUNT(F6,H6,J6)=3,F6*H6*J6,"") | L6: =IF(K6="","",IF(OR(F6>=9,K6>=100,AND(F6>=7,J6>=7)),"ACTION REQUIRED","Monitor")) | M6: A-01 | N6: 3 Automated control | O6: 9 | P6: 3 | Q6: 3 | R6: =IF(COUNT(O6,P6,Q6)=3,O6*P6*Q6,"") | S6: =IF(AND(O6<>"",F6<>"",O6<>F6),"SEVERITY CHANGED","") | T6: Abrasive condition monitored each shift; low-pressure alarm on the line control system; profile verified at lot start and every two hours.
A7: C-1.2 | B7: 1 | C7: Surface preparation | D7: Surface contamination not removed (oil, soluble salts, moisture) | E7: localized disbondment and blistering | F7: 8 | G7: Oil carryover in compressed air; contaminated recycled abrasive | H7: 4 | I7: Blotter test at shift start; visual | J7: 7 | K7: =IF(COUNT(F7,H7,J7)=3,F7*H7*J7,"") | L7: =IF(K7="","",IF(OR(F7>=9,K7>=100,AND(F7>=7,J7>=7)),"ACTION REQUIRED","Monitor")) | M7: A-02 | N7: 3 Automated control | O7: 8 | P7: 3 | Q7: 4 | R7: =IF(COUNT(O7,P7,Q7)=3,O7*P7*Q7,"") | S7: =IF(AND(O7<>"",F7<>"",O7<>F7),"SEVERITY CHANGED","") | T7: Soluble salt testing added at defined frequency; air dryer and coalescing filter verified with a differential pressure alarm.
A8: C-1.3 | B8: 1 | C8: Surface preparation | D8: Flash rust between blast and coating | E8: rust layer trapped beneath the film | F8: 8 | G8: Blast-to-coat interval exceeded; steel temperature close to dew point | H8: 5 | I8: Operator judgment on holding time | J8: 7 | K8: =IF(COUNT(F8,H8,J8)=3,F8*H8*J8,"") | L8: =IF(K8="","",IF(OR(F8>=9,K8>=100,AND(F8>=7,J8>=7)),"ACTION REQUIRED","Monitor")) | M8: A-03 | N8: 2 Error-proof | O8: 8 | P8: 2 | Q8: 3 | R8: =IF(COUNT(O8,P8,Q8)=3,O8*P8*Q8,"") | S8: =IF(AND(O8<>"",F8<>"",O8<>F8),"SEVERITY CHANGED","") | T8: Maximum blast-to-coat interval enforced by the line tracking system; continuous dew point and steel temperature monitoring with automatic hold.
A9: Stage 2—Induction heating
A10: C-2.1 | B10: 2 | C10: Induction heating | D10: Pipe surface temperature below the specified window | E10: incomplete powder fusion; porosity, holidays, low adhesion | F10: 9 | G10: Induction power drift; line speed variation; uncalibrated pyrometer | H10: 6 | I10: Pyrometer reading, operator monitored | J10: 6 | K10: =IF(COUNT(F10,H10,J10)=3,F10*H10*J10,"") | L10: =IF(K10="","",IF(OR(F10>=9,K10>=100,AND(F10>=7,J10>=7)),"ACTION REQUIRED","Monitor")) | M10: A-04 | N10: 2 Error-proof | O10: 9 | P10: 2 | Q10: 2 | R10: =IF(COUNT(O10,P10,Q10)=3,O10*P10*Q10,"") | S10: =IF(AND(O10<>"",F10<>"",O10<>F10),"SEVERITY CHANGED","") | T10: Closed-loop temperature control: pyrometer feedback to induction power with automatic line stop outside the window. Temperature logged per pipe identifier.
A11: C-2.2 | B11: 2 | C11: Induction heating | D11: Pipe overheated above the window | E11: powder degradation; brittle coating; cracking | F11: 8 | G11: Induction left energized during a line stop | H11: 4 | I11: Pyrometer reading, operator monitored | J11: 6 | K11: =IF(COUNT(F11,H11,J11)=3,F11*H11*J11,"") | L11: =IF(K11="","",IF(OR(F11>=9,K11>=100,AND(F11>=7,J11>=7)),"ACTION REQUIRED","Monitor")) | M11: A-05 | N11: 2 Error-proof | O11: 8 | P11: 2 | Q11: 2 | R11: =IF(COUNT(O11,P11,Q11)=3,O11*P11*Q11,"") | S11: =IF(AND(O11<>"",F11<>"",O11<>F11),"SEVERITY CHANGED","") | T11: Induction power interlocked to line motion; power cuts automatically on line stop.
A12: C-2.3 | B12: 2 | C12: Induction heating | D12: Non-uniform circumferential temperature | E12: uneven fusion; variable film thickness | F12: 7 | G12: Coil misalignment; wall thickness variation | H12: 4 | I12: Single-point pyrometer only | J12: 8 | K12: =IF(COUNT(F12,H12,J12)=3,F12*H12*J12,"") | L12: =IF(K12="","",IF(OR(F12>=9,K12>=100,AND(F12>=7,J12>=7)),"ACTION REQUIRED","Monitor")) | M12: A-06 | N12: 4 Detection | O12: 7 | P12: 3 | Q12: 4 | R12: =IF(COUNT(O12,P12,Q12)=3,O12*P12*Q12,"") | S12: =IF(AND(O12<>"",F12<>"",O12<>F12),"SEVERITY CHANGED","") | T12: Scanning pyrometer at coating entry; coil alignment added to preventive maintenance.
A13: Stage 3—Epoxy application
A14: C-3.1 | B14: 3 | C14: Epoxy application | D14: Dry film thickness below minimum | E14: insufficient corrosion protection; premature failure in service | F14: 9 | G14: Line speed high; low powder feed; worn nozzles | H14: 5 | I14: DFT gauge, sampled | J14: 5 | K14: =IF(COUNT(F14,H14,J14)=3,F14*H14*J14,"") | L14: =IF(K14="","",IF(OR(F14>=9,K14>=100,AND(F14>=7,J14>=7)),"ACTION REQUIRED","Monitor")) | M14: A-07 | N14: 3 Automated control | O14: 9 | P14: 3 | Q14: 3 | R14: =IF(COUNT(O14,P14,Q14)=3,O14*P14*Q14,"") | S14: =IF(AND(O14<>"",F14<>"",O14<>F14),"SEVERITY CHANGED","") | T14: Powder feed interlocked to line speed with alarm outside the thickness band; nozzles replaced on a run-hours schedule.
A15: C-3.2 | B15: 3 | C15: Epoxy application | D15: Dry film thickness above maximum | E15: cracking risk; dimensional interference at the field joint | F15: 6 | G15: Line speed low; excessive feed rate | H15: 5 | I15: DFT gauge, sampled | J15: 5 | K15: =IF(COUNT(F15,H15,J15)=3,F15*H15*J15,"") | L15: =IF(K15="","",IF(OR(F15>=9,K15>=100,AND(F15>=7,J15>=7)),"ACTION REQUIRED","Monitor")) | M15: A-08 | N15: 3 Automated control | O15: 6 | P15: 3 | Q15: 3 | R15: =IF(COUNT(O15,P15,Q15)=3,O15*P15*Q15,"") | S15: =IF(AND(O15<>"",F15<>"",O15<>F15),"SEVERITY CHANGED","") | T15: Same interlocked control, upper limit.
A16: C-3.3 | B16: 3 | C16: Epoxy application | D16: Pinholes and holidays | E16: bare steel exposed; localized corrosion and cathodic disbondment | F16: 9 | G16: Steel outgassing; residual contamination; booth humidity | H16: 6 | I16: 100% holiday detection downstream | J16: 3 | K16: =IF(COUNT(F16,H16,J16)=3,F16*H16*J16,"") | L16: =IF(K16="","",IF(OR(F16>=9,K16>=100,AND(F16>=7,J16>=7)),"ACTION REQUIRED","Monitor")) | M16: A-09 | N16: 1 Eliminate cause | O16: 9 | P16: 3 | Q16: 3 | R16: =IF(COUNT(O16,P16,Q16)=3,O16*P16*Q16,"") | S16: =IF(AND(O16<>"",F16<>"",O16<>F16),"SEVERITY CHANGED","") | T16: Aimed at the cause, not the detection: preheat hold defined for outgassing-prone grades; booth humidity controlled and recorded; Stage 1 contamination actions closed out.
A17: Stage 4—Cooling and quench
A18: C-4.1 | B18: 4 | C18: Cooling and quench | D18: Quench applied before minimum cure time | E18: incomplete cross-linking; low chemical and disbondment resistance | F18: 9 | G18: Line speed high for the quench station position | H18: 4 | I18: Cure verification on a lot sample | J18: 5 | K18: =IF(COUNT(F18,H18,J18)=3,F18*H18*J18,"") | L18: =IF(K18="","",IF(OR(F18>=9,K18>=100,AND(F18>=7,J18>=7)),"ACTION REQUIRED","Monitor")) | M18: A-10 | N18: 2 Error-proof | O18: 9 | P18: 2 | Q18: 4 | R18: =IF(COUNT(O18,P18,Q18)=3,O18*P18*Q18,"") | S18: =IF(AND(O18<>"",F18<>"",O18<>F18),"SEVERITY CHANGED","") | T18: Minimum cure time before quench interlocked to line speed; lot held pending the cure verification result.
A19: C-4.2 | B19: 4 | C19: Cooling and quench | D19: Thermal shock cracking from excessive cooling rate | E19: through-coating cracks | F19: 8 | G19: Quench water temperature low; quench positioned too close | H19: 3 | I19: Visual plus holiday detection | J19: 4 | K19: =IF(COUNT(F19,H19,J19)=3,F19*H19*J19,"") | L19: =IF(K19="","",IF(OR(F19>=9,K19>=100,AND(F19>=7,J19>=7)),"ACTION REQUIRED","Monitor")) | R19: =IF(COUNT(O19,P19,Q19)=3,O19*P19*Q19,"") | S19: =IF(AND(O19<>"",F19<>"",O19<>F19),"SEVERITY CHANGED","")
A20: C-4.3 | B20: 4 | C20: Cooling and quench | D20: Blistering from entrapped moisture or gas | E20: localized disbondment | F20: 8 | G20: Moisture on steel; substrate outgassing | H20: 3 | I20: 100% visual plus holiday detection | J20: 5 | K20: =IF(COUNT(F20,H20,J20)=3,F20*H20*J20,"") | L20: =IF(K20="","",IF(OR(F20>=9,K20>=100,AND(F20>=7,J20>=7)),"ACTION REQUIRED","Monitor")) | M20: A-11 | N20: 3 Automated control | O20: 8 | P20: 2 | Q20: 4 | R20: =IF(COUNT(O20,P20,Q20)=3,O20*P20*Q20,"") | S20: =IF(AND(O20<>"",F20<>"",O20<>F20),"SEVERITY CHANGED","") | T20: Quench water temperature and quality controlled and recorded with alarm on deviation.
A21: Stage 5—Holiday detection
A22: C-5.1 | B22: 5 | C22: Holiday detection | D22: Detector voltage set below the value required for the specified film thickness | E22: real holidays pass undetected; defective pipe released | F22: 10 | G22: Voltage not adjusted for coating thickness; wrong product recipe selected | H22: 4 | I22: Operator sets voltage per procedure | J22: 8 | K22: =IF(COUNT(F22,H22,J22)=3,F22*H22*J22,"") | L22: =IF(K22="","",IF(OR(F22>=9,K22>=100,AND(F22>=7,J22>=7)),"ACTION REQUIRED","Monitor")) | M22: A-12 | N22: 2 Error-proof | O22: 10 | P22: 2 | Q22: 2 | R22: =IF(COUNT(O22,P22,Q22)=3,O22*P22*Q22,"") | S22: =IF(AND(O22<>"",F22<>"",O22<>F22),"SEVERITY CHANGED","") | T22: Detector verified daily against a reference standard containing an artificial holiday of known size; voltage locked per product code in the recipe.
A23: C-5.2 | B23: 5 | C23: Holiday detection | D23: DFT gauge out of calibration | E23: out-of-specification coating accepted | F23: 8 | G23: Annual calibration only; wrong substrate calibration | H23: 3 | I23: Calibration label | J23: 7 | K23: =IF(COUNT(F23,H23,J23)=3,F23*H23*J23,"") | L23: =IF(K23="","",IF(OR(F23>=9,K23>=100,AND(F23>=7,J23>=7)),"ACTION REQUIRED","Monitor")) | M23: A-13 | N23: 4 Detection | O23: 8 | P23: 2 | Q23: 3 | R23: =IF(COUNT(O23,P23,Q23)=3,O23*P23*Q23,"") | S23: =IF(AND(O23<>"",F23<>"",O23<>F23),"SEVERITY CHANGED","") | T23: Zero and reference verification at each shift start, recorded on the inspection sheet.
A24: C-5.3 | B24: 5 | C24: Holiday detection | D24: Traceability lost between coating and inspection | E24: nonconforming pipe cannot be segregated | F24: 9 | G24: Marking removed by blasting or coating; manual transcription | H24: 4 | I24: Manual pipe number record | J24: 6 | K24: =IF(COUNT(F24,H24,J24)=3,F24*H24*J24,"") | L24: =IF(K24="","",IF(OR(F24>=9,K24>=100,AND(F24>=7,J24>=7)),"ACTION REQUIRED","Monitor")) | M24: A-14 | N24: 2 Error-proof | O24: 9 | P24: 2 | Q24: 3 | R24: =IF(COUNT(O24,P24,Q24)=3,O24*P24*Q24,"") | S24: =IF(AND(O24<>"",F24<>"",O24<>F24),"SEVERITY CHANGED","") | T24: Durable re-marking after blasting; identifier scanned at each station and tied to the process data log.
A25: Stage 6—Repair and release
A26: C-6.1 | B26: 6 | C26: Repair and release | D26: Repair applied outside the repair material’s specified conditions | E26: patch disbonds in service | F26: 9 | G26: Ambient temperature or humidity out of specification; mix ratio error; expired material | H26: 5 | I26: Written repair procedure | J26: 7 | K26: =IF(COUNT(F26,H26,J26)=3,F26*H26*J26,"") | L26: =IF(K26="","",IF(OR(F26>=9,K26>=100,AND(F26>=7,J26>=7)),"ACTION REQUIRED","Monitor")) | M26: A-15 | N26: 2 Error-proof | O26: 9 | P26: 2 | Q26: 3 | R26: =IF(COUNT(O26,P26,Q26)=3,O26*P26*Q26,"") | S26: =IF(AND(O26<>"",F26<>"",O26<>F26),"SEVERITY CHANGED","") | T26: Pre-measured two-component repair cartridges eliminate mix ratio error; FIFO and expiry check at issue; repair conditions recorded; repair operators qualified.
A27: C-6.2 | B27: 6 | C27: Repair and release | D27: Repaired area exceeds the allowable size or density | E27: pipe accepted that should have been stripped | F27: 8 | G27: No cumulative tracking of repairs per pipe | H27: 5 | I27: Operator judgment | J27: 8 | K27: =IF(COUNT(F27,H27,J27)=3,F27*H27*J27,"") | L27: =IF(K27="","",IF(OR(F27>=9,K27>=100,AND(F27>=7,J27>=7)),"ACTION REQUIRED","Monitor")) | M27: A-16 | N27: 3 Automated control | O27: 8 | P27: 2 | Q27: 3 | R27: =IF(COUNT(O27,P27,Q27)=3,O27*P27*Q27,"") | S27: =IF(AND(O27<>"",F27<>"",O27<>F27),"SEVERITY CHANGED","") | T27: Repair log per pipe identifier with cumulative count and area; QA disposition required above the specified limit.
A28: C-6.3 | B28: 6 | C28: Repair and release | D28: Repaired pipe released without holiday retest | E28: defect escapes to the customer | F28: 10 | G28: Step skipped under schedule pressure | H28: 3 | I28: Procedure and QA signature | J28: 6 | K28: =IF(COUNT(F28,H28,J28)=3,F28*H28*J28,"") | L28: =IF(K28="","",IF(OR(F28>=9,K28>=100,AND(F28>=7,J28>=7)),"ACTION REQUIRED","Monitor")) | M28: A-17 | N28: 2 Error-proof | O28: 10 | P28: 1 | Q28: 2 | R28: =IF(COUNT(O28,P28,Q28)=3,O28*P28*Q28,"") | S28: =IF(AND(O28<>"",F28<>"",O28<>F28),"SEVERITY CHANGED","") | T28: Release blocked in the system until a holiday retest result is recorded against the pipe identifier.
K29: =IF(COUNT(F29,H29,J29)=3,F29*H29*J29,"") | L29: =IF(K29="","",IF(OR(F29>=9,K29>=100,AND(F29>=7,J29>=7)),"ACTION REQUIRED","Monitor")) | R29: =IF(COUNT(O29,P29,Q29)=3,O29*P29*Q29,"") | S29: =IF(AND(O29<>"",F29<>"",O29<>F29),"SEVERITY CHANGED","")
K30: =IF(COUNT(F30,H30,J30)=3,F30*H30*J30,"") | L30: =IF(K30="","",IF(OR(F30>=9,K30>=100,AND(F30>=7,J30>=7)),"ACTION REQUIRED","Monitor")) | R30: =IF(COUNT(O30,P30,Q30)=3,O30*P30*Q30,"") | S30: =IF(AND(O30<>"",F30<>"",O30<>F30),"SEVERITY CHANGED","")

Sheet EXAMPLE C Assembly
A1: EXAMPLE C ASSEMBLY
A2: Hydraulic cylinder assembly and pressure test—complete worked register from Part 2. Read, do not edit.
A4: Risk ID | B4: Step | C4: Process step | D4: Failure mode | E4: Effect of failure | F4: S | G4: Cause | H4: O | I4: Current control | J4: D | K4: RPN | L4: Trigger | M4: Action ID | N4: Action level | O4: Res. S | P4: Res. O | Q4: Res. D | R4: Res. RPN | S4: Check | T4: Action taken
A5: Steps 1–2—Receipt, kitting and cleanliness
A6: A-1.1 | B6: 1 | C6: Receipt and kitting | D6: Wrong seal compound issued to the job | E6: seal degrades against the service fluid; loss of containment in service | F6: 9 | G6: Compounds packaged alike; kitting by description rather than part number | H6: 5 | I6: Visual check of the kit | J6: 7 | K6: =IF(COUNT(F6,H6,J6)=3,F6*H6*J6,"") | L6: =IF(K6="","",IF(OR(F6>=9,K6>=100,AND(F6>=7,J6>=7)),"ACTION REQUIRED","Monitor")) | M6: A-01 | N6: 2 Error-proof | O6: 9 | P6: 2 | Q6: 3 | R6: =IF(COUNT(O6,P6,Q6)=3,O6*P6*Q6,"") | S6: =IF(AND(O6<>"",F6<>"",O6<>F6),"SEVERITY CHANGED","") | T6: Kitting by part number with a scanned pick confirmation; compounds separated by color-coded bin and stored apart.
A7: A-1.2 | B7: 1 | C7: Receipt and kitting | D7: Seal used beyond shelf life | E7: hardening and leakage in service | F7: 8 | G7: No FIFO enforcement; cure date not visible at issue | H7: 5 | I7: Stores judgment | J7: 8 | K7: =IF(COUNT(F7,H7,J7)=3,F7*H7*J7,"") | L7: =IF(K7="","",IF(OR(F7>=9,K7>=100,AND(F7>=7,J7>=7)),"ACTION REQUIRED","Monitor")) | M7: A-02 | N7: 2 Error-proof | O7: 8 | P7: 1 | Q7: 3 | R7: =IF(COUNT(O7,P7,Q7)=3,O7*P7*Q7,"") | S7: =IF(AND(O7<>"",F7<>"",O7<>F7),"SEVERITY CHANGED","") | T7: Cure date printed on the issue label; FIFO enforced by the stores system, which blocks issue of expired stock.
A8: A-2.1 | B8: 2 | C8: Cleanliness | D8: Particulate contamination remaining in the tube bore | E8: seal scored on first stroke; internal leakage | F8: 8 | G8: Wash cycle never validated for the tube length; no cleanliness acceptance criterion | H8: 6 | I8: Visual | J8: 8 | K8: =IF(COUNT(F8,H8,J8)=3,F8*H8*J8,"") | L8: =IF(K8="","",IF(OR(F8>=9,K8>=100,AND(F8>=7,J8>=7)),"ACTION REQUIRED","Monitor")) | M8: A-03 | N8: 3 Automated control | O8: 8 | P8: 2 | Q8: 4 | R8: =IF(COUNT(O8,P8,Q8)=3,O8*P8*Q8,"") | S8: =IF(AND(O8<>"",F8<>"",O8<>F8),"SEVERITY CHANGED","") | T8: Wash cycle validated for full tube length; cleanliness acceptance criterion defined and verified by sampled particle count.
A9: Steps 3–4—Seal fitting, piston assembly and torque
A10: A-3.1 | B10: 3 | C10: Seal fitting | D10: Seal cut passing over a port or thread during fitting | E10: external leak | F10: 8 | G10: No fitting sleeve or thread protector; assembly by hand | H10: 6 | I10: Pressure test at step 8 | J10: 4 | K10: =IF(COUNT(F10,H10,J10)=3,F10*H10*J10,"") | L10: =IF(K10="","",IF(OR(F10>=9,K10>=100,AND(F10>=7,J10>=7)),"ACTION REQUIRED","Monitor")) | M10: A-04 | N10: 2 Error-proof | O10: 8 | P10: 2 | Q10: 4 | R10: =IF(COUNT(O10,P10,Q10)=3,O10*P10*Q10,"") | S10: =IF(AND(O10<>"",F10<>"",O10<>F10),"SEVERITY CHANGED","") | T10: Fitting sleeve introduced as standard tooling; assembly cannot be performed without it.
A11: A-3.2 | B11: 3 | C11: Seal fitting | D11: Seal fitted inverted or in the wrong groove | E11: leakage or early failure | F11: 8 | G11: Similar groove geometry; text-only work instruction | H11: 4 | I11: Visual | J11: 6 | K11: =IF(COUNT(F11,H11,J11)=3,F11*H11*J11,"") | L11: =IF(K11="","",IF(OR(F11>=9,K11>=100,AND(F11>=7,J11>=7)),"ACTION REQUIRED","Monitor")) | M11: A-05 | N11: 5 Procedure | O11: 8 | P11: 3 | Q11: 4 | R11: =IF(COUNT(O11,P11,Q11)=3,O11*P11*Q11,"") | S11: =IF(AND(O11<>"",F11<>"",O11<>F11),"SEVERITY CHANGED","") | T11: Illustrated work instruction at the station showing seal orientation; first-build check by a second person.
A12: A-4.1 | B12: 4 | C12: Piston torque | D12: Piston nut torque below specification | E12: piston loosens in service; loss of function | F12: 9 | G12: Torque wrench not verified; value not displayed at the station | H12: 4 | I12: Operator | J12: 7 | K12: =IF(COUNT(F12,H12,J12)=3,F12*H12*J12,"") | L12: =IF(K12="","",IF(OR(F12>=9,K12>=100,AND(F12>=7,J12>=7)),"ACTION REQUIRED","Monitor")) | M12: A-06 | N12: 3 Automated control | O12: 9 | P12: 2 | Q12: 4 | R12: =IF(COUNT(O12,P12,Q12)=3,O12*P12*Q12,"") | S12: =IF(AND(O12<>"",F12<>"",O12<>F12),"SEVERITY CHANGED","") | T12: Torque wrench verified at shift start against a reference; torque value displayed at the station; value recorded per unit.
A13: A-4.2 | B13: 4 | C13: Piston torque | D13: Thread locking compound omitted | E13: nut backs off in service | F13: 9 | G13: Manual step leaving no evidence once assembled | H13: 4 | I13: None after assembly | J13: 9 | K13: =IF(COUNT(F13,H13,J13)=3,F13*H13*J13,"") | L13: =IF(K13="","",IF(OR(F13>=9,K13>=100,AND(F13>=7,J13>=7)),"ACTION REQUIRED","Monitor")) | M13: A-07 | N13: 1 Eliminate cause | O13: 9 | P13: 1 | Q13: 4 | R13: =IF(COUNT(O13,P13,Q13)=3,O13*P13*Q13,"") | S13: =IF(AND(O13<>"",F13<>"",O13<>F13),"SEVERITY CHANGED","") | T13: Pre-applied thread-locking patch on the nut, eliminating the manual step entirely.
A14: Steps 5–7—Insertion, gland fitting, ports
A15: A-5.1 | B15: 5 | C15: Insertion | D15: Rod or bore scored during insertion | E15: internal leakage and premature wear | F15: 7 | G15: Insertion by hand without a guide; misalignment | H15: 5 | I15: Function test | J15: 5 | K15: =IF(COUNT(F15,H15,J15)=3,F15*H15*J15,"") | L15: =IF(K15="","",IF(OR(F15>=9,K15>=100,AND(F15>=7,J15>=7)),"ACTION REQUIRED","Monitor")) | M15: A-08 | N15: 2 Error-proof | O15: 7 | P15: 2 | Q15: 5 | R15: =IF(COUNT(O15,P15,Q15)=3,O15*P15*Q15,"") | S15: =IF(AND(O15<>"",F15<>"",O15<>F15),"SEVERITY CHANGED","") | T15: Insertion guide added; alignment no longer dependent on hand control.
A16: A-6.1 | B16: 6 | C16: Gland fitting | D16: Gland bolts tightened out of sequence or under torque | E16: distortion and leak path | F16: 8 | G16: Sequence not specified; no torque record | H16: 5 | I16: Pressure test | J16: 5 | K16: =IF(COUNT(F16,H16,J16)=3,F16*H16*J16,"") | L16: =IF(K16="","",IF(OR(F16>=9,K16>=100,AND(F16>=7,J16>=7)),"ACTION REQUIRED","Monitor")) | M16: A-09 | N16: 4 Detection | O16: 8 | P16: 3 | Q16: 4 | R16: =IF(COUNT(O16,P16,Q16)=3,O16*P16*Q16,"") | S16: =IF(AND(O16<>"",F16<>"",O16<>F16),"SEVERITY CHANGED","") | T16: Tightening sequence specified on the instruction; torque recorded per unit against the serial number.
A17: A-7.1 | B17: 7 | C17: Ports | D17: Port fitting over-tightened | E17: thread damage or cracked boss | F17: 8 | G17: No torque value for fittings; fitted by feel | H17: 5 | I17: Pressure test | J17: 5 | K17: =IF(COUNT(F17,H17,J17)=3,F17*H17*J17,"") | L17: =IF(K17="","",IF(OR(F17>=9,K17>=100,AND(F17>=7,J17>=7)),"ACTION REQUIRED","Monitor")) | M17: A-10 | N17: 4 Detection | O17: 8 | P17: 3 | Q17: 4 | R17: =IF(COUNT(O17,P17,Q17)=3,O17*P17*Q17,"") | S17: =IF(AND(O17<>"",F17<>"",O17<>F17),"SEVERITY CHANGED","") | T17: Torque value specified for each fitting size; wrench issued to the station.
A18: Step 8—Hydrostatic proof test
A19: A-8.1 | B19: 8 | C19: Pressure test | D19: Test conducted below the specified test pressure | E19: a defective unit passes | F19: 10 | G19: Regulator setting; gauge selection; no recorded pressure trace | H19: 4 | I19: Operator reading a dial | J19: 8 | K19: =IF(COUNT(F19,H19,J19)=3,F19*H19*J19,"") | L19: =IF(K19="","",IF(OR(F19>=9,K19>=100,AND(F19>=7,J19>=7)),"ACTION REQUIRED","Monitor")) | M19: A-11 | N19: 3 Automated control | O19: 10 | P19: 2 | Q19: 2 | R19: =IF(COUNT(O19,P19,Q19)=3,O19*P19*Q19,"") | S19: =IF(AND(O19<>"",F19<>"",O19<>F19),"SEVERITY CHANGED","") | T19: Test rig fitted with a pressure transducer and chart recorder; pressure trace retained against the serial number. The dial is no longer the record.
A20: A-8.2 | B20: 8 | C20: Pressure test | D20: Pressure held for less than the specified duration | E20: slow leaks not revealed | F20: 10 | G20: Duration neither timed nor recorded; throughput pressure | H20: 5 | I20: Operator | J20: 8 | K20: =IF(COUNT(F20,H20,J20)=3,F20*H20*J20,"") | L20: =IF(K20="","",IF(OR(F20>=9,K20>=100,AND(F20>=7,J20>=7)),"ACTION REQUIRED","Monitor")) | M20: A-12 | N20: 2 Error-proof | O20: 10 | P20: 1 | Q20: 2 | R20: =IF(COUNT(O20,P20,Q20)=3,O20*P20*Q20,"") | S20: =IF(AND(O20<>"",F20<>"",O20<>F20),"SEVERITY CHANGED","") | T20: Hold duration timed automatically by the rig; the test cannot be marked complete before the timer expires.
A21: A-8.3 | B21: 8 | C21: Pressure test | D21: Test gauge out of calibration | E21: unit passes at a pressure below the true requirement | F21: 10 | G21: Annual calibration only; no verification against a reference | H21: 3 | I21: Calibration label | J21: 8 | K21: =IF(COUNT(F21,H21,J21)=3,F21*H21*J21,"") | L21: =IF(K21="","",IF(OR(F21>=9,K21>=100,AND(F21>=7,J21>=7)),"ACTION REQUIRED","Monitor")) | M21: A-13 | N21: 2 Error-proof | O21: 10 | P21: 2 | Q21: 2 | R21: =IF(COUNT(O21,P21,Q21)=3,O21*P21*Q21,"") | S21: =IF(AND(O21<>"",F21<>"",O21<>F21),"SEVERITY CHANGED","") | T21: Rig transducer verified daily against a reference gauge; verification recorded and the rig locked out on failure.
